<?xml version="1.0"?>
<robot name="tasfiq_robot">
    <material name="black">
        <color rgba="0 0 0 1"/>
    </material>
    <material name="silver">
        <color rgba="0.5 0.5 0.5 1"/>
    </material>
    <material name="white">
        <color rgba="1 1 1 1"/>
    </material>
    <material name="red">
        <color rgba="1 0 0 1"/>
    </material>
    <link name="robot_body">
        <visual>
            <geometry>
                <box size="0.4 0.4 0.4"/>
            </geometry>
            <material name='black'/>
            <origin xyz="0.0 0.0 0.3" rpy="0.0 0.0 0.0"/>
        </visual>
        <collision>
            <geometry>
                <box size="0.4 0.4 0.4"/>
            </geometry>
            <origin xyz="0.0 0.0 0.3" rpy="0.0 0.0 0.0"/>
        </collision>
    </link>
    <link name="left_hand">
        <visual>
            <geometry>
                <cylinder radius="0.04" length="0.3"/>
            </geometry>
            <origin xyz="0.03 0.0 -0.1" rpy="0.0 2.61 0.0"/>
            <material name='white'/>
        </visual>
        <collision>
            <geometry>
                <cylinder radius="0.04" length="0.3"/>
            </geometry>
            <origin xyz="0.03 0.0 -0.1" rpy="0.0 2.61 0.0"/>
        </collision>
        <inertial>
            <mass value="0.5"/>
            <inertia ixx="0.3" ixy="0.0" ixz="0.0" iyy="0.3" iyz="0.0" izz="0.3"/>
        </inertial>
    </link>
    <link name="right_hand">
        <visual>
            <geometry>
                <cylinder radius="0.05" length="0.3"/>
            </geometry>
            <origin xyz="-0.03 0.0 -0.1" rpy="0.0 -2.61 0.0"/>
            <material name='white'/>
        </visual>
        <collision>
            <geometry>
                <cylinder radius="0.04" length="0.3"/>
            </geometry>
            <origin xyz="-0.03 0.0 -0.1" rpy="0.0 -2.61 0.0"/>
        </collision>
        <inertial>
            <mass value="0.5"/>
            <inertia ixx="0.3" ixy="0.0" ixz="0.0" iyy="0.3" iyz="0.0" izz="0.3"/>
        </inertial>
    </link>
    <joint name="left_joint" type="fixed">
        <parent link="robot_body"/>
        <child link="left_hand"/>
        <origin xyz="0.2 0.0 0.4"/>
    </joint>
    <joint name="right_joint" type="fixed">
        <parent link="robot_body"/>
        <child link="right_hand"/>
        <origin xyz="-0.2 0.0 0.4"/>
    </joint>
    <link name="cute_head">
        <visual>
            <geometry>
                <sphere radius="0.2"/>
            </geometry>
            <material name='silver'/>
        </visual>
        <collision>
            <geometry>
                <sphere radius="0.2"/>
            </geometry>
        </collision>
        <inertial>
            <mass value="10"/>
            <inertia ixx="0.3" ixy="0.0" ixz="0.0" iyy="0.3" iyz="0.0" izz="0.3"/>
        </inertial>
    </link>
    <joint name="head_joint" type="fixed">
        <parent link="robot_body"/>
        <child link="cute_head"/>
        <origin xyz="0.0 0.0 0.5" rpy="0.0 0.0 0.0"/>
    </joint>
    <link name="left_front_wheel">
        <visual>
            <geometry>
                <cylinder radius="0.1" length="0.05"/>
            </geometry>
            <material name='red'/>
        </visual>
        <collision>
            <geometry>
                <cylinder radius="0.1" length="0.05"/>
            </geometry>
        </collision>
        <inertial>
            <mass value="0.3"/>
            <inertia ixx="0.5" ixy="0.0" ixz="0.0" iyy="0.5" iyz="0.0" izz="0.5"/>
        </inertial>
    </link>
    <joint name="left_front_wheel_joint" type="continuous">
        <parent link="robot_body"/>
        <child link="left_front_wheel"/>
        <axis xyz="0.0 0.0 1.0"/>
        <origin xyz="0.2 0.2 0.1" rpy="0.0 1.57 0.0"/>
    </joint>
    <link name="right_front_wheel">
        <visual>
            <geometry>
                <cylinder radius="0.1" length="0.05"/>
            </geometry>
            <material name='red'/>
        </visual>
        <collision>
            <geometry>
                <cylinder radius="0.1" length="0.05"/>
            </geometry>
        </collision>
        <inertial>
            <mass value="0.3"/>
            <inertia ixx="0.5" ixy="0.0" ixz="0.0" iyy="0.5" iyz="0.0" izz="0.5"/>
        </inertial>
    </link>
    <joint name="right_front_wheel_joint" type="continuous">
        <parent link="robot_body"/>
        <child link="right_front_wheel"/>
        <axis xyz="0.0 0.0 1.0"/>
        <origin xyz="-0.2 0.2 0.1" rpy="0.0 1.57 0.0"/>
    </joint>
    <link name="left_back_wheel">
        <visual>
            <geometry>
                <cylinder radius="0.1" length="0.05"/>
            </geometry>
            <material name='red'/>
        </visual>
        <collision>
            <geometry>
                <cylinder radius="0.1" length="0.05"/>
            </geometry>
        </collision>
        <inertial>
            <mass value="0.3"/>
            <inertia ixx="0.5" ixy="0.0" ixz="0.0" iyy="0.5" iyz="0.0" izz="0.5"/>
        </inertial>
    </link>
    <joint name="left_back_wheel_joint" type="continuous">
        <parent link="robot_body"/>
        <child link="left_back_wheel"/>
        <axis xyz="0.0 0.0 1.0"/>
        <origin xyz="0.2 -0.2 0.1" rpy="0.0 1.57 0.0"/>
    </joint>
    <link name="right_back_wheel">
        <visual>
            <geometry>
                <cylinder radius="0.1" length="0.05"/>
            </geometry>
            <material name='red'/>
        </visual>
        <collision>
            <geometry>
                <cylinder radius="0.1" length="0.05"/>
            </geometry>
        </collision>
        <inertial>
            <mass value="0.3"/>
            <inertia ixx="0.5" ixy="0.0" ixz="0.0" iyy="0.5" iyz="0.0" izz="0.5"/>
        </inertial>
    </link>
    <joint name="right_back_wheel_joint" type="continuous">
        <parent link="robot_body"/>
        <child link="right_back_wheel"/>
        <axis xyz="0.0 0.0 1.0"/>
        <origin xyz="-0.2 -0.2 0.1" rpy="0.0 1.57 0.0"/>
    </joint>

    <gazebo reference="left_front_wheel">
      <mu1 value="200.0"/>
      <mu2 value="100.0"/>
      <kp value="10000000.0" />
      <kd value="1.0" />
      <material>Gazebo/Grey</material>
    </gazebo>
    <gazebo reference="right_front_wheel">
      <mu1 value="200.0"/>
      <mu2 value="100.0"/>
      <kp value="10000000.0" />
      <kd value="1.0" />
      <material>Gazebo/Grey</material>
    </gazebo>
    <gazebo reference="left_back_wheel">
      <mu1 value="200.0"/>
      <mu2 value="100.0"/>
      <kp value="10000000.0" />
      <kd value="1.0" />
      <material>Gazebo/Grey</material>
    </gazebo>
    <gazebo reference="right_back_wheel">
      <mu1 value="200.0"/>
      <mu2 value="100.0"/>
      <kp value="10000000.0" />
      <kd value="1.0" />
      <material>Gazebo/Grey</material>
    </gazebo>

    <!-- This block connects the wheel joint to an actuator (motor), which informs both
    simulation and visualization of the robot -->
    <transmission name="left_front_wheel_trans">
      <type>transmission_interface/SimpleTransmission</type>
      <actuator name="robot_wheel_motor">
        <mechanicalReduction>1</mechanicalReduction>
      </actuator>
      <joint name="left_front_wheel_joint">
        <hardwareInterface>hardware_interface/VelocityJointInterface</hardwareInterface>
      </joint>
    </transmission>
    <transmission name="right_front_wheel_trans">
      <type>transmission_interface/SimpleTransmission</type>
      <actuator name="robot_wheel_motor">
        <mechanicalReduction>1</mechanicalReduction>
      </actuator>
      <joint name="right_front_wheel_joint">
        <hardwareInterface>hardware_interface/VelocityJointInterface</hardwareInterface>
      </joint>
    </transmission>
    <transmission name="left_back_wheel_trans">
      <type>transmission_interface/SimpleTransmission</type>
      <actuator name="robot_wheel_motor">
        <mechanicalReduction>1</mechanicalReduction>
      </actuator>
      <joint name="left_back_wheel_joint">
        <hardwareInterface>hardware_interface/VelocityJointInterface</hardwareInterface>
      </joint>
    </transmission>
    <transmission name="right_back_wheel_trans">
      <type>transmission_interface/SimpleTransmission</type>
      <actuator name="robot_wheel_motor">
        <mechanicalReduction>1</mechanicalReduction>
      </actuator>
      <joint name="right_back_wheel_joint">
        <hardwareInterface>hardware_interface/VelocityJointInterface</hardwareInterface>
      </joint>
    </transmission>

    <gazebo>
        <plugin name="gazebo_ros_control" filename="libgazebo_ros_control.so">
         <robotNamespace>/</robotNamespace>
        </plugin>
    </gazebo>

</robot>